Workbook

Sheet History Kebocoran
B2: No | C2: Deskripsi Pipa | D2: Deskripsi Kegiatan | E2: TIME | G2: Bocor | H2: Clamp | I2: Sadel | J2: Sisip | K2: Tanggal | N2: Keterangan | O2: Lokasi SUMUR
E3: Start Time | F3: End Time | G3: Titik | H3: Titik | I3: Titik | J3: Meter | K3: Kejadian | L3: Mulai Perbaikan | M3: Selesai Perbaikan
G4: =SUM(G6:G4647) -> 3532 | H4: =SUM(H6:H4647) -> 647 | I4: =SUM(I6:I4647) -> 1912.3 | J4: =SUM(J6:J3545) -> 54329.932 | P4: Bulan | Q4: tahun | R4: KP | S4: Struktur | T4: Distrik | U4: Dimensi Pipa | V4: Panjang Pipa
B5: No | C5: Deskripsi Pipa | D5: Deskripsi Kegiatan | E5: Start Time | F5: End Time | G5: Bocor | H5: Clamp | I5: Sadel | J5: Sisip | K5: Kejadian | L5: Mulai Perbaikan | M5: Selesai Perbaikan | N5: Keterangan | O5: Lokasi | P5: Bulan | Q5: tahun | R5: KP | S5: Struktur | T5: Distrik | U5: Dimensi Pipa | V5: Panjang Pipa | W5: Column1
B6: 1 | G6: 1 | I6: 2 | K6: 43101 | P6: 1 | Q6: 2018 | S6: =IF(C6="TRUNKLINE",LEFT(O6,25),IF(C6="PIPING",LEFT(O6,13),LEFT(O6,3))) | T6: =IFERROR(VLOOKUP(S6,[1]LOKASI!$B$4:$D$19,2,0),"-") -> -
B7: =B6+1 -> 2 | G7: 1 | I7: 1 | K7: 43101 | P7: 1 | Q7: 2018 | S7: =IF(C7="TRUNKLINE",LEFT(O7,25),IF(C7="PIPING",LEFT(O7,13),LEFT(O7,3))) | T7: =IFERROR(VLOOKUP(S7,[1]LOKASI!$B$4:$D$19,2,0),"-") -> -
B8: =B7+1 -> 3 | C8: TRUNKLINE | G8: 1 | H8: 1 | K8: 43101 | O8: TLJ-TTB | P8: 1 | Q8: 2018 | S8: =IF(C8="TRUNKLINE",LEFT(O8,25),IF(C8="PIPING",LEFT(O8,13),LEFT(O8,3))) -> TLJ-TTB | T8: =IFERROR(VLOOKUP(S8,[1]LOKASI!$B$4:$D$19,2,0),"-") -> -
B9: =B8+1 -> 4 | C9: FLOWLINE | G9: 1 | I9: 1 | K9: 43102 | O9: TLJ-184 | P9: 1 | Q9: 2018 | S9: =IF(C9="TRUNKLINE",LEFT(O9,25),IF(C9="PIPING",LEFT(O9,13),LEFT(O9,3))) -> TLJ | T9: =IFERROR(VLOOKUP(S9,[1]LOKASI!$B$4:$D$19,2,0),"-") -> DISTRIK I
B10: =B9+1 -> 5 | G10: 1 | I10: 1 | K10: 43102 | O10: TLJ-190 | P10: 1 | Q10: 2018 | S10: =IF(C10="TRUNKLINE",LEFT(O10,25),IF(C10="PIPING",LEFT(O10,13),LEFT(O10,3))) -> TLJ | T10: =IFERROR(VLOOKUP(S10,[1]LOKASI!$B$4:$D$19,2,0),"-") -> DISTRIK I
B11: =B10+1 -> 6 | G11: 1 | I11: 1 | K11: 43102 | O11: TLJ-156 | P11: 1 | Q11: 2018 | S11: =IF(C11="TRUNKLINE",LEFT(O11,25),IF(C11="PIPING",LEFT(O11,13),LEFT(O11,3))) -> TLJ | T11: =IFERROR(VLOOKUP(S11,[1]LOKASI!$B$4:$D$19,2,0),"-") -> DISTRIK I
B12: =B11+1 -> 7 | G12: 1 | I12: 1 | K12: 43104 | O12: PMB-32 | P12: 1 | Q12: 2018 | S12: =IF(C12="TRUNKLINE",LEFT(O12,25),IF(C12="PIPING",LEFT(O12,13),LEFT(O12,3))) -> PMB | T12: =IFERROR(VLOOKUP(S12,[1]LOKASI!$B$4:$D$19,2,0),"-") -> DISTRIK I
B13: =B12+1 -> 8 | G13: 1 | J13: 24 | K13: 43104 | O13: BRG-09 | P13: 1 | Q13: 2018 | S13: =IF(C13="TRUNKLINE",LEFT(O13,25),IF(C13="PIPING",LEFT(O13,13),LEFT(O13,3))) -> BRG | T13: =IFERROR(VLOOKUP(S13,[1]LOKASI!$B$4:$D$19,2,0),"-") -> DISTRIK III
B14: =B13+1 -> 9 | G14: 1 | H14: 1 | K14: 43104 | O14: BRG-20 | P14: 1 | Q14: 2018 | S14: =IF(C14="TRUNKLINE",LEFT(O14,25),IF(C14="PIPING",LEFT(O14,13),LEFT(O14,3))) -> BRG | T14: =IFERROR(VLOOKUP(S14,[1]LOKASI!$B$4:$D$19,2,0),"-") -> DISTRIK III
B15: =B14+1 -> 10 | C15: TRUNKLINE | D15: Bocor korosif | G15: 1 | I15: 1 | K15: 43105 | L15: 43105 | M15: 43105 | O15: SP7TLJ-SP9TLJ | P15: 1 | Q15: 2018 | S15: =IF(C15="TRUNKLINE",LEFT(O15,25),IF(C15="PIPING",LEFT(O15,13),LEFT(O15,3))) -> SP7TLJ-SP9TLJ | T15: =IFERROR(VLOOKUP(S15,[1]LOKASI!$B$4:$D$19,2,0),"-") -> -
B16: =B15+1 -> 11 | G16: 1 | J16: 9 | K16: 43105 | O16: TLJ-169 | P16: 1 | Q16: 2018 | S16: =IF(C16="TRUNKLINE",LEFT(O16,25),IF(C16="PIPING",LEFT(O16,13),LEFT(O16,3))) -> TLJ | T16: =IFERROR(VLOOKUP(S16,[1]LOKASI!$B$4:$D$19,2,0),"-") -> DISTRIK I
B17: =B16+1 -> 12 | J17: 12 | K17: 43106 | O17: GNK-91 | P17: 1 | Q17: 2018 | S17: =IF(C17="TRUNKLINE",LEFT(O17,25),IF(C17="PIPING",LEFT(O17,13),LEFT(O17,3))) -> GNK | T17: =IFERROR(VLOOKUP(S17,[1]LOKASI!$B$4:$D$19,2,0),"-") -> DISTRIK I
B18: =B17+1 -> 13 | C18: FLOWLINE | D18: HEADER FLOWLINE | G18: 1 | I18: 1 | K18: 43108 | O18: GNK-91 | P18: 1 | Q18: 2018 | S18: =IF(C18="TRUNKLINE",LEFT(O18,25),IF(C18="PIPING",LEFT(O18,13),LEFT(O18,3))) -> GNK | T18: =IFERROR(VLOOKUP(S18,[1]LOKASI!$B$4:$D$19,2,0),"-") -> DISTRIK I
B19: =B18+1 -> 14 | D19: SISIP ELBOW | G19: 1 | J19: 1 | K19: 43108 | O19: OGN-32 | P19: 1 | Q19: 2018 | S19: =IF(C19="TRUNKLINE",LEFT(O19,25),IF(C19="PIPING",LEFT(O19,13),LEFT(O19,3))) -> OGN | T19: =IFERROR(VLOOKUP(S19,[1]LOKASI!$B$4:$D$19,2,0),"-") -> DISTRIK II
B20: =B19+1 -> 15 | C20: TRUNKLINE | J20: 144 | K20: 43110 | L20: 43110 | M20: 43112 | O20: LBK-PPP | P20: 1 | Q20: 2018 | S20: =IF(C20="TRUNKLINE",LEFT(O20,25),IF(C20="PIPING",LEFT(O20,13),LEFT(O20,3))) -> LBK-PPP | T20: =IFERROR(VLOOKUP(S20,[1]LOKASI!$B$4:$D$19,2,0),"-") -> -
B21: =B20+1 -> 16 | J21: 12 | K21: 43113 | O21: GNK-80 | P21: 1 | Q21: 2018 | S21: =IF(C21="TRUNKLINE",LEFT(O21,25),IF(C21="PIPING",LEFT(O21,13),LEFT(O21,3))) -> GNK | T21: =IFERROR(VLOOKUP(S21,[1]LOKASI!$B$4:$D$19,2,0),"-") -> DISTRIK I
B22: =B21+1 -> 17 | C22: TRUNKLINE | G22: 1 | I22: 1 | K22: 43115 | O22: SP1GNK-SP2GNK | P22: 1 | Q22: 2018 | S22: =IF(C22="TRUNKLINE",LEFT(O22,25),IF(C22="PIPING",LEFT(O22,13),LEFT(O22,3))) -> SP1GNK-SP2GNK | T22: =IFERROR(VLOOKUP(S22,[1]LOKASI!$B$4:$D$19,2,0),"-") -> -
B23: =B22+1 -> 18 | G23: 1 | I23: 1 | K23: 43115 | O23: TTB-33 | P23: 1 | Q23: 2018 | S23: =IF(C23="TRUNKLINE",LEFT(O23,25),IF(C23="PIPING",LEFT(O23,13),LEFT(O23,3))) -> TTB | T23: =IFERROR(VLOOKUP(S23,[1]LOKASI!$B$4:$D$19,2,0),"-") -> DISTRIK II
B24: =B23+1 -> 19 | C24: TRUNKLINE | D24: 4 INCH | G24: 1 | I24: 1 | K24: 43115 | N24: GERGAJIAN OTK | O24: BRGC-BRGD | P24: 1 | Q24: 2018 | S24: =IF(C24="TRUNKLINE",LEFT(O24,25),IF(C24="PIPING",LEFT(O24,13),LEFT(O24,3))) -> BRGC-BRGD | T24: =IFERROR(VLOOKUP(S24,[1]LOKASI!$B$4:$D$19,2,0),"-") -> -
B25: =B24+1 -> 20 | G25: 1 | I25: 1 | K25: 43116 | O25: TLJ-165 | P25: 1 | Q25: 2018 | S25: =IF(C25="TRUNKLINE",LEFT(O25,25),IF(C25="PIPING",LEFT(O25,13),LEFT(O25,3))) -> TLJ | T25: =IFERROR(VLOOKUP(S25,[1]LOKASI!$B$4:$D$19,2,0),"-") -> DISTRIK I
B26: =B25+1 -> 21 | G26: 1 | I26: 1 | K26: 43116 | O26: TLJ-169 | P26: 1 | Q26: 2018 | S26: =IF(C26="TRUNKLINE",LEFT(O26,25),IF(C26="PIPING",LEFT(O26,13),LEFT(O26,3))) -> TLJ | T26: =IFERROR(VLOOKUP(S26,[1]LOKASI!$B$4:$D$19,2,0),"-") -> DISTRIK I
B27: =B26+1 -> 22 | G27: 1 | I27: 1 | K27: 43116 | O27: TLJ-190 | P27: 1 | Q27: 2018 | S27: =IF(C27="TRUNKLINE",LEFT(O27,25),IF(C27="PIPING",LEFT(O27,13),LEFT(O27,3))) -> TLJ | T27: =IFERROR(VLOOKUP(S27,[1]LOKASI!$B$4:$D$19,2,0),"-") -> DISTRIK I
B28: =B27+1 -> 23 | C28: TRUNKLINE | G28: 1 | H28: 1 | K28: 43116 | O28: LBK-PPP | P28: 1 | Q28: 2018 | S28: =IF(C28="TRUNKLINE",LEFT(O28,25),IF(C28="PIPING",LEFT(O28,13),LEFT(O28,3))) -> LBK-PPP | T28: =IFERROR(VLOOKUP(S28,[1]LOKASI!$B$4:$D$19,2,0),"-") -> -
B29: =B28+1 -> 24 | G29: 1 | I29: 1 | K29: 43117 | O29: TLJ-36 | P29: 1 | Q29: 2018 | S29: =IF(C29="TRUNKLINE",LEFT(O29,25),IF(C29="PIPING",LEFT(O29,13),LEFT(O29,3))) -> TLJ | T29: =IFERROR(VLOOKUP(S29,[1]LOKASI!$B$4:$D$19,2,0),"-") -> DISTRIK I
B30: =B29+1 -> 25 | G30: 1 | I30: 1 | K30: 43118 | O30: TLJ-02 | P30: 1 | Q30: 2018 | S30: =IF(C30="TRUNKLINE",LEFT(O30,25),IF(C30="PIPING",LEFT(O30,13),LEFT(O30,3))) -> TLJ | T30: =IFERROR(VLOOKUP(S30,[1]LOKASI!$B$4:$D$19,2,0),"-") -> DISTRIK I
B31: =B30+1 -> 26 | G31: 1 | I31: 1 | K31: 43118 | O31: TLJ-169 | P31: 1 | Q31: 2018 | S31: =IF(C31="TRUNKLINE",LEFT(O31,25),IF(C31="PIPING",LEFT(O31,13),LEFT(O31,3))) -> TLJ | T31: =IFERROR(VLOOKUP(S31,[1]LOKASI!$B$4:$D$19,2,0),"-") -> DISTRIK I
B32: =B31+1 -> 27 | G32: 1 | I32: 1 | K32: 43118 | O32: TTB-33 | P32: 1 | Q32: 2018 | S32: =IF(C32="TRUNKLINE",LEFT(O32,25),IF(C32="PIPING",LEFT(O32,13),LEFT(O32,3))) -> TTB | T32: =IFERROR(VLOOKUP(S32,[1]LOKASI!$B$4:$D$19,2,0),"-") -> DISTRIK II
B33: =B32+1 -> 28 | J33: 24 | K33: 43119 | O33: TLJ-02 | P33: 1 | Q33: 2018 | S33: =IF(C33="TRUNKLINE",LEFT(O33,25),IF(C33="PIPING",LEFT(O33,13),LEFT(O33,3))) -> TLJ | T33: =IFERROR(VLOOKUP(S33,[1]LOKASI!$B$4:$D$19,2,0),"-") -> DISTRIK I
B34: =B33+1 -> 29 | G34: 1 | J34: 36 | K34: 43119 | M34: 43126 | O34: BRG-28 | P34: 1 | Q34: 2018 | S34: =IF(C34="TRUNKLINE",LEFT(O34,25),IF(C34="PIPING",LEFT(O34,13),LEFT(O34,3))) -> BRG | T34: =IFERROR(VLOOKUP(S34,[1]LOKASI!$B$4:$D$19,2,0),"-") -> DISTRIK III
B35: =B34+1 -> 30 | K35: 43119 | O35: PMB-26 | P35: 1 | Q35: 2018 | S35: =IF(C35="TRUNKLINE",LEFT(O35,25),IF(C35="PIPING",LEFT(O35,13),LEFT(O35,3))) -> PMB | T35: =IFERROR(VLOOKUP(S35,[1]LOKASI!$B$4:$D$19,2,0),"-") -> DISTRIK I
B36: =B35+1 -> 31 | G36: 1 | I36: 1 | K36: 43119 | O36: PMB-12 | P36: 1 | Q36: 2018 | S36: =IF(C36="TRUNKLINE",LEFT(O36,25),IF(C36="PIPING",LEFT(O36,13),LEFT(O36,3))) -> PMB | T36: =IFERROR(VLOOKUP(S36,[1]LOKASI!$B$4:$D$19,2,0),"-") -> DISTRIK I
B37: =B36+1 -> 32 | G37: 1 | J37: 12 | K37: 43120 | O37: TLJ-236 | P37: 1 | Q37: 2018 | S37: =IF(C37="TRUNKLINE",LEFT(O37,25),IF(C37="PIPING",LEFT(O37,13),LEFT(O37,3))) -> TLJ | T37: =IFERROR(VLOOKUP(S37,[1]LOKASI!$B$4:$D$19,2,0),"-") -> DISTRIK I
B38: =B37+1 -> 33 | D38: GANTI STREAMLINE | G38: 1 | J38: 6 | K38: 43120 | O38: BRG-08 | P38: 1 | Q38: 2018 | S38: =IF(C38="TRUNKLINE",LEFT(O38,25),IF(C38="PIPING",LEFT(O38,13),LEFT(O38,3))) -> BRG | T38: =IFERROR(VLOOKUP(S38,[1]LOKASI!$B$4:$D$19,2,0),"-") -> DISTRIK III
B39: =B38+1 -> 34 | J39: 228 | K39: 43120 | O39: BRG-08 | P39: 1 | Q39: 2018 | S39: =IF(C39="TRUNKLINE",LEFT(O39,25),IF(C39="PIPING",LEFT(O39,13),LEFT(O39,3))) -> BRG | T39: =IFERROR(VLOOKUP(S39,[1]LOKASI!$B$4:$D$19,2,0),"-") -> DISTRIK III
B40: =B39+1 -> 35 | D40: PASANG BARU | J40: 4500 | K40: 43121 | O40: TMT-37 | P40: 1 | Q40: 2018 | S40: =IF(C40="TRUNKLINE",LEFT(O40,25),IF(C40="PIPING",LEFT(O40,13),LEFT(O40,3))) -> TMT | T40: =IFERROR(VLOOKUP(S40,[1]LOKASI!$B$4:$D$19,2,0),"-") -> DISTRIK II
B41: =B40+1 -> 36 | G41: 1 | I41: 1 | K41: 43121 | O41: TLJ-111 | P41: 1 | Q41: 2018 | S41: =IF(C41="TRUNKLINE",LEFT(O41,25),IF(C41="PIPING",LEFT(O41,13),LEFT(O41,3))) -> TLJ | T41: =IFERROR(VLOOKUP(S41,[1]LOKASI!$B$4:$D$19,2,0),"-") -> DISTRIK I
...

Sheet Monitoring Inspeksi
N2: O4722 | P2: G
N3: O5645
N4: jenis perbaikan | O4: dilakukan/tidak dilakukan | P4: Diminta ke zona
A5: No. | B5: Category Pipeline | C5: From | D5: To | E5: Size Inch | F5: Length (m) | G5: Service Fluid | H5: Year Built | I5: Ansi Rating | J5: Corrotion Rate | K5: Remain Life | L5: Design Pressure | M5: Leak Event | N5: Perbaikan | O5: NDT | P5: PLO | Q5: Integrity Status | R5: Memo Inspeksi | S5: Hasil Inspeksi | T5: Tindak Lanjut2
A6: 1 | B6: TRUNKLINE | C6: SP 2 TMT | D6: SP 1 TMT | E6: 6 | F6: 8711 | G6: OIL | I6: 150 | L6: 280 | M6: =SUMIF('History Kebocoran'!$O:$O, Table1[From], 'History Kebocoran'!$G:$G) -> 6 | Q6: =IF(M6=0, "GOOD", IF(M6>5, "BAD", "MONITOR")) -> BAD
A7: 2 | B7: TRUNKLINE | C7: SP 1 TMT | D7: SP OGAN | E7: 6 | F7: 11046 | G7: OIL | I7: 150 | L7: 280 | M7: =SUMIF('History Kebocoran'!$O:$O, Table1[From], 'History Kebocoran'!$G:$G) -> 16 | N7: Sisip | Q7: =IF(M7=0, "GOOD", IF(M7>5, "BAD", "MONITOR")) -> BAD
A8: 3 | B8: TRUNKLINE | C8: SP KUANG | D8: SKG PAGAR DEWA | E8: 10 | F8: 13000 | G8: GAS | L8: 840 | M8: =SUMIF('History Kebocoran'!$O:$O, Table1[From], 'History Kebocoran'!$G:$G) -> 2 | Q8: =IF(M8=0, "GOOD", IF(M8>5, "BAD", "MONITOR")) -> MONITOR
A9: 4 | B9: TRUNKLINE | C9: SP III GUNUNG KEMALA | D9: SKG III GUNUNG KEMALA | E9: 10 | F9: 2980 | G9: GAS | L9: 680 | M9: =SUMIF('History Kebocoran'!$O:$O, Table1[From], 'History Kebocoran'!$G:$G) -> 0 | Q9: =IF(M9=0, "GOOD", IF(M9>5, "BAD", "MONITOR")) -> GOOD
A10: 5 | B10: TRUNKLINE | C10: SP OGAN | D10: SP 1 TANJUNG TIGA BARAT | E10: 6 | F10: 14000 | G10: OIL | H10: 2017 | I10: 150 | L10: 300 | M10: =SUMIF('History Kebocoran'!$O:$O, Table1[From], 'History Kebocoran'!$G:$G) -> 17 | N10: Sisip | Q10: =IF(M10=0, "GOOD", IF(M10>5, "BAD", "MONITOR")) -> BAD
A11: 6 | B11: TRUNKLINE | C11: SKG X PRABUMULIH BARAT | D11: SPG PAGAR DEWA | E11: 32 | F11: 46542 | G11: GAS | L11: 1129 | M11: =SUMIF('History Kebocoran'!$O:$O, Table1[From], 'History Kebocoran'!$G:$G) -> 0 | Q11: =IF(M11=0, "GOOD", IF(M11>5, "BAD", "MONITOR")) -> GOOD
A12: 7 | B12: TRUNKLINE | C12: SPG PAGAR DEWA | D12: PPP PRABUMULIH | E12: 6 | F12: 47615 | G12: OIL | L12: 139.96 | M12: =SUMIF('History Kebocoran'!$O:$O, Table1[From], 'History Kebocoran'!$G:$G) -> 0 | Q12: =IF(M12=0, "GOOD", IF(M12>5, "BAD", "MONITOR")) -> GOOD
A13: 8 | B13: TRUNKLINE | C13: SP II GNK | D13: PPP PRABUMULIH | E13: 4 & 6 | F13: 14266 | G13: OIL | L13: 599.94 | M13: =SUMIF('History Kebocoran'!$O:$O, Table1[From], 'History Kebocoran'!$G:$G) -> 10 | Q13: =IF(M13=0, "GOOD", IF(M13>5, "BAD", "MONITOR")) -> BAD
A14: 9 | B14: TRUNKLINE | C14: SP KUANG | D14: SPG KUANG | E14: 8 | F14: 1977 | G14: GAS | L14: 164.99 | M14: =SUMIF('History Kebocoran'!$O:$O, Table1[From], 'History Kebocoran'!$G:$G) -> 2 | Q14: =IF(M14=0, "GOOD", IF(M14>5, "BAD", "MONITOR")) -> MONITOR
A15: 10 | B15: TRUNKLINE | C15: SP PBM BARAT | D15: SP I GUNUNG KEMALA | E15: 4 | F15: 20065 | G15: GAS | L15: 740.18 | M15: =SUMIF('History Kebocoran'!$O:$O, Table1[From], 'History Kebocoran'!$G:$G) -> 0 | Q15: =IF(M15=0, "GOOD", IF(M15>5, "BAD", "MONITOR")) -> GOOD
A16: 11 | B16: TRUNKLINE | C16: SPG KUANG | D16: JUMPER KUANG | E16: 10 | F16: 2026 | G16: GAS | L16: 499.95 | M16: =SUMIF('History Kebocoran'!$O:$O, Table1[From], 'History Kebocoran'!$G:$G) -> 0 | Q16: =IF(M16=0, "GOOD", IF(M16>5, "BAD", "MONITOR")) -> GOOD
A17: 12 | B17: TRUNKLINE | C17: SPG KUANG | D17: SP KUANG | E17: 4 | F17: 1970 | G17: KONDENSAT | L17: 99.99 | M17: =SUMIF('History Kebocoran'!$O:$O, Table1[From], 'History Kebocoran'!$G:$G) -> 0 | Q17: =IF(M17=0, "GOOD", IF(M17>5, "BAD", "MONITOR")) -> GOOD
A18: 13 | B18: TRUNKLINE | C18: SPG MERBAU | D18: SP PAGAR DEWA | E18: 4 | F18: 22065 | G18: KONDENSAT | L18: 99.99 | M18: =SUMIF('History Kebocoran'!$O:$O, Table1[From], 'History Kebocoran'!$G:$G) -> 5 | Q18: =IF(M18=0, "GOOD", IF(M18>5, "BAD", "MONITOR")) -> MONITOR
A19: 14 | B19: TRUNKLINE | C19: PPP PRABUMULIH | D19: KM 3 PLAJU (8") | E19: 8 | F19: 93000 | G19: OIL | L19: 740 | M19: =SUMIF('History Kebocoran'!$O:$O, Table1[From], 'History Kebocoran'!$G:$G) -> 0 | Q19: =IF(M19=0, "GOOD", IF(M19>5, "BAD", "MONITOR")) -> GOOD
A20: 15 | B20: TRUNKLINE | C20: PPP PRABUMULIH | D20: KM 3 PLAJU (10") | E20: 10 | F20: 93000 | G20: OIL | L20: 740 | M20: =SUMIF('History Kebocoran'!$O:$O, Table1[From], 'History Kebocoran'!$G:$G) -> 0 | Q20: =IF(M20=0, "GOOD", IF(M20>5, "BAD", "MONITOR")) -> GOOD
A21: 16 | B21: TRUNKLINE | C21: SPU LIMAU BARAT | D21: PPP PRABUMULIH | E21: 12 | F21: 18980 | G21: OIL | L21: 740 | M21: =SUMIF('History Kebocoran'!$O:$O, Table1[From], 'History Kebocoran'!$G:$G) -> 0 | Q21: =IF(M21=0, "GOOD", IF(M21>5, "BAD", "MONITOR")) -> GOOD
A22: 17 | B22: TRUNKLINE | C22: SP LEMBAK | D22: PPP PRABUMULIH | E22: 6 | F22: 26500 | G22: KONDENSAT | L22: 650 | M22: =SUMIF('History Kebocoran'!$O:$O, Table1[From], 'History Kebocoran'!$G:$G) -> 3 | Q22: =IF(M22=0, "GOOD", IF(M22>5, "BAD", "MONITOR")) -> MONITOR
A23: 18 | B23: TRUNKLINE | C23: SP BERINGIN C | D23: SP BERINGIN D (8") | E23: 8 | F23: 7450 | G23: GAS | L23: 1023 | M23: =SUMIF('History Kebocoran'!$O:$O, Table1[From], 'History Kebocoran'!$G:$G) -> 0 | Q23: =IF(M23=0, "GOOD", IF(M23>5, "BAD", "MONITOR")) -> GOOD
A24: 19 | B24: TRUNKLINE | C24: SP BERINGIN A | D24: SP BERINGIN C | E24: 8 | F24: 8742 | G24: GAS | L24: 1023 | M24: =SUMIF('History Kebocoran'!$O:$O, Table1[From], 'History Kebocoran'!$G:$G) -> 0 | Q24: =IF(M24=0, "GOOD", IF(M24>5, "BAD", "MONITOR")) -> GOOD
A25: 20 | B25: TRUNKLINE | C25: SP KUANG | D25: JUMPER KUANG | E25: 6 | F25: 3500 | G25: OIL | L25: 0 | M25: =SUMIF('History Kebocoran'!$O:$O, Table1[From], 'History Kebocoran'!$G:$G) -> 2 | Q25: =IF(M25=0, "GOOD", IF(M25>5, "BAD", "MONITOR")) -> MONITOR
A26: 21 | B26: TRUNKLINE | C26: SP V TL. JIMAR | D26: PPP PRABUMULIH | E26: 6 | F26: 10000 | G26: OIL | L26: 0 | M26: =SUMIF('History Kebocoran'!$O:$O, Table1[From], 'History Kebocoran'!$G:$G) -> 0 | Q26: =IF(M26=0, "GOOD", IF(M26>5, "BAD", "MONITOR")) -> GOOD
A27: 22 | B27: TRUNKLINE | C27: SP TANJUNG TIGA BARAT | D27: PPP PRABUMULIH | E27: 8 | F27: 20000 | G27: OIL | H27: 2013 | I27: 150 | L27: 0 | M27: =SUMIF('History Kebocoran'!$O:$O, Table1[From], 'History Kebocoran'!$G:$G) -> 0 | Q27: =IF(M27=0, "GOOD", IF(M27>5, "BAD", "MONITOR")) -> GOOD
A28: 23 | B28: INJECTION LINE | C28: PMB-01 | D28: SP PMB | E28: 3 | F28: 900 | G28: WATER | M28: =SUMIF('History Kebocoran'!$O:$O, Table1[From], 'History Kebocoran'!$G:$G) -> 0 | Q28: =IF(M28=0, "GOOD", IF(M28>5, "BAD", "MONITOR")) -> GOOD
A29: 24 | B29: TRUNKLINE | C29: SP BERINGIN C | D29: SP BERINGIN D (4") | E29: 4 | F29: 7296 | G29: OIL | L29: 800 | M29: =SUMIF('History Kebocoran'!$O:$O, Table1[From], 'History Kebocoran'!$G:$G) -> 0 | Q29: =IF(M29=0, "GOOD", IF(M29>5, "BAD", "MONITOR")) -> GOOD
A30: 25 | B30: TRUNKLINE | C30: SP PAKU GAJAH | D30: SPG MERBAU | E30: 12 | F30: 22192 | G30: GAS | L30: 895 | M30: =SUMIF('History Kebocoran'!$O:$O, Table1[From], 'History Kebocoran'!$G:$G) -> 0 | Q30: =IF(M30=0, "GOOD", IF(M30>5, "BAD", "MONITOR")) -> GOOD
A31: 26 | B31: TRUNKLINE | C31: SPG PAGAR DEWA | D31: SP PAKU GAJAH | E31: 10 | F31: 401 | G31: GAS | L31: 499.95 | M31: =SUMIF('History Kebocoran'!$O:$O, Table1[From], 'History Kebocoran'!$G:$G) -> 0 | Q31: =IF(M31=0, "GOOD", IF(M31>5, "BAD", "MONITOR")) -> GOOD
A32: 27 | B32: TRUNKLINE | C32: SPG MERBAU | D32: SPG PAGAR DEWA | E32: 14 | F32: 22092 | G32: GAS | L32: 780 | M32: =SUMIF('History Kebocoran'!$O:$O, Table1[From], 'History Kebocoran'!$G:$G) -> 5 | Q32: =IF(M32=0, "GOOD", IF(M32>5, "BAD", "MONITOR")) -> MONITOR
A33: 28 | B33: TRUNKLINE | C33: SP VI TL. JIMAR | D33: PPP PRABUMULIH | E33: 6 & 8 | F33: 5000 | G33: OIL | L33: 740 | M33: =SUMIF('History Kebocoran'!$O:$O, Table1[From], 'History Kebocoran'!$G:$G) -> 0 | Q33: =IF(M33=0, "GOOD", IF(M33>5, "BAD", "MONITOR")) -> GOOD
A34: 29 | B34: TRUNKLINE | C34: SP 3 GNK | D34: SIMPANG GNK 68 | E34: 2.375, 3.5 & 4 | F34: 10175 | G34: Gas | L34: 740 | M34: =SUMIF('History Kebocoran'!$O:$O, Table1[From], 'History Kebocoran'!$G:$G) -> 9 | Q34: =IF(M34=0, "GOOD", IF(M34>5, "BAD", "MONITOR")) -> BAD
A35: 30 | B35: TRUNKLINE | C35: SP 3 GUNUNG KEMALA | D35: SKG 3 GUNUNG KEMALA | E35: 10 | F35: 3010 | G35: Gas | L35: 680 | M35: =SUMIF('History Kebocoran'!$O:$O, Table1[From], 'History Kebocoran'!$G:$G) -> 0 | Q35: =IF(M35=0, "GOOD", IF(M35>5, "BAD", "MONITOR")) -> GOOD
A36: 31 | B36: TRUNKLINE | C36: SKG 3 GUNUNG KEMALA | D36: SKG 10 PRABUMULIH | E36: 8 | F36: 10910 | G36: Gas | L36: 888 | M36: =SUMIF('History Kebocoran'!$O:$O, Table1[From], 'History Kebocoran'!$G:$G) -> 0 | Q36: =IF(M36=0, "GOOD", IF(M36>5, "BAD", "MONITOR")) -> GOOD
A37: 32 | B37: TRUNKLINE | C37: MANIFOLD PRBUMENANG | D37: SPG PAKU GAJAH | E37: 6 & 8 | F37: 11505 (NPS 6 CS), 410 (NPS 6 SS), & 1000 (NPS 8 CS) | G37: Gas | L37: 740 | M37: =SUMIF('History Kebocoran'!$O:$O, Table1[From], 'History Kebocoran'!$G:$G) -> 0 | Q37: =IF(M37=0, "GOOD", IF(M37>5, "BAD", "MONITOR")) -> GOOD
A38: 33 | B38: FLOW LINE | C38: TDN-001 | D38: SKG X Prabumulih Barat | F38: 15000 | G38: GAS | H38: 1994 | M38: =SUMIF('History Kebocoran'!$O:$O, Table1[From], 'History Kebocoran'!$G:$G) -> 0 | Q38: =IF(M38=0, "GOOD", IF(M38>5, "BAD", "MONITOR")) -> GOOD
A39: 34 | B39: FLOW LINE | C39: TLJ-025 | D39: SP 2 Talang Jimar | E39: 3 | F39: 900 | G39: OIL | H39: 1939 | M39: =SUMIF('History Kebocoran'!$O:$O, Table1[From], 'History Kebocoran'!$G:$G) -> 1 | Q39: =IF(M39=0, "GOOD", IF(M39>5, "BAD", "MONITOR")) -> MONITOR
A40: 35 | B40: FLOW LINE | C40: TLJ-060 | D40: SP 2 Talang Jimar | E40: 3 | F40: 1550 | G40: OIL | H40: 1940 | M40: =SUMIF('History Kebocoran'!$O:$O, Table1[From], 'History Kebocoran'!$G:$G) -> 5 | Q40: =IF(M40=0, "GOOD", IF(M40>5, "BAD", "MONITOR")) -> MONITOR
A41: 36 | B41: FLOW LINE | C41: TLJ-104 | D41: SP 2 Talang Jimar | E41: 3 | F41: 400 | G41: OIL | H41: 1943 | M41: =SUMIF('History Kebocoran'!$O:$O, Table1[From], 'History Kebocoran'!$G:$G) -> 4 | Q41: =IF(M41=0, "GOOD", IF(M41>5, "BAD", "MONITOR")) -> MONITOR
...

Sheet Contoh
A5: No | B5: WK | C5: Cluster | D5: Status | E5: Dari (nama Sumur) | F5: Ke (Nama Stasium Pengumpul) | G5: Nama Flowline | H5: Jenis Sumur | I5: Key | J5: Panjang | K5: Tahun Konstruksi | L5: Column4 | M5: Tahun | N5: Jumlah Kejadian (2023-2024) | O5: Note | P5: Jumlah Titik Inspeksi | Q5: Priority | R5: Tanggal Inspeksi | S5: Note Pengujian | T5: Report Inspeksi | U5: Berita Acara Inspeksi | V5: RLA Document | W5: RE Document | X5: Analisa Resiko | Y5: Tanggal Terbit COI/PLO | Z5: Sertifikat Berlaku | AA5: COI/PLO | AB5: RLT < 3 THN | AC5: RLT 3-5 THN | AD5: RLT > 5 THN | AE5: Integrity Status
A6: 1 | B6: Prabumulih | C6: Cluster Flowline Gas SKG XI Lembak | D6: Aktif | E6: LBK-004 | F6: SKG XI Lembak | G6: Flowline dari LBK-004 ke SKG XI Lembak | H6: GAS WELL | I6: SKG XI Lembak-GAS WELL | J6: 431 | K6: 12-Feb-1980 | L6: 2005 | M6: 1980 | P6: 4.31 | Q6: P1 | R6: 45795 | S6: Menyesuaikan panjang act | V6: PEP-PBM-PL-RLA-1801A | W6: PEP-PBM-PL-RE-1801A | AB6: #N/A | AC6: #N/A | AD6: #N/A
A7: 2 | B7: Prabumulih | C7: Cluster Flowline Gas SKG XI Lembak | D7: Aktif | E7: LBK-005 | F7: SKG XI Lembak | G7: Flowline dari LBK-005 ke SKG XI Lembak | H7: GAS WELL | I7: SKG XI Lembak-GAS WELL | J7: 1198 | K7: 24-May-1981 | L7: 2005 | M7: 1981 | N7: 1 | P7: 11.98 | Q7: P1 | R7: 45736 | S7: Menyesuaikan panjang act | V7: PEP-PBM-PL-RLA-1801B | W7: PEP-PBM-PL-RE-1801B | AB7: 0 | AC7: 0 | AD7: 0
A8: 3 | B8: Prabumulih | C8: Cluster Flowline Gas SKG XI Lembak | D8: Aktif | E8: LBK-007 | F8: SKG XI Lembak | G8: Flowline dari LBK-007 ke SKG XI Lembak | H8: GAS WELL | I8: SKG XI Lembak-GAS WELL | J8: 1441 | K8: 15-Nov-1982 | L8: 2005 | M8: 1982 | P8: 14.41 | Q8: P1 | R8: 45729 | S8: Menyesuaikan panjang act | V8: PEP-PBM-PL-RLA-1801C | W8: PEP-PBM-PL-RE-1801C | AB8: 0 | AC8: 0 | AD8: 0
A9: 4 | B9: Prabumulih | C9: Cluster Flowline Gas SKG XI Lembak | D9: Aktif | E9: LBK-009 | F9: SKG XI Lembak | G9: Flowline dari LBK-009 ke SKG XI Lembak | H9: GAS WELL | I9: SKG XI Lembak-GAS WELL | J9: 1087 | K9: 14-Mar-1992 | L9: 2005 | M9: 1992 | P9: 10.87 | Q9: P1 | R9: 45729 | S9: Menyesuaikan panjang act | V9: PEP-PBM-PL-RLA-1801D | W9: PEP-PBM-PL-RE-1801D | AB9: 2740 | AC9: 0 | AD9: 50 | AE9: BAD
A10: 5 | B10: Prabumulih | C10: Cluster Flowline Gas SKG XI Lembak | D10: Aktif | E10: LBK-010 | F10: SKG XI Lembak | G10: Flowline dari LBK-010 ke SKG XI Lembak | H10: GAS WELL | I10: SKG XI Lembak-GAS WELL | J10: 752 | K10: 30-May-1992 | L10: 2005 | M10: 1992 | P10: 7.52 | Q10: P1 | R10: 45732 | S10: Menyesuaikan panjang act | V10: PEP-PBM-PL-RLA-1801E | W10: PEP-PBM-PL-RE-1801E | AB10: 0 | AC10: 0 | AD10: 0
A11: 6 | B11: Prabumulih | C11: Cluster Flowline Gas SKG XI Lembak | D11: Aktif | E11: LBK-011 | F11: SKG XI Lembak | G11: Flowline dari LBK-011 ke SKG XI Lembak | H11: GAS WELL | I11: SKG XI Lembak-GAS WELL | J11: 1742 | K11: 02-Sep-1992 | L11: 2005 | M11: 1992 | N11: 1 | P11: 17.42 | Q11: P1 | R11: 45795 | S11: Menyesuaikan panjang act | V11: PEP-PBM-PL-RLA-1801F | W11: PEP-PBM-PL-RE-1801F | AB11: 0 | AC11: 0 | AD11: 0
A12: 7 | B12: Prabumulih | C12: Cluster Flowline Gas SKG XI Lembak | D12: Aktif | E12: LBK-012 | F12: SKG XI Lembak | G12: Flowline dari LBK-012 ke SKG XI Lembak | H12: GAS WELL | I12: SKG XI Lembak-GAS WELL | J12: 2344 | K12: 13-Aug-2008 | L12: 2008 | M12: 2008 | P12: 23.44 | Q12: P1 | R12: 45733 | S12: Menyesuaikan panjang act | V12: PEP-PBM-PL-RLA-1801G | W12: PEP-PBM-PL-RE-1801G | AB12: 0 | AC12: 0 | AD12: 0
A13: 8 | B13: Prabumulih | C13: Cluster Flowline Gas SKG XI Lembak | D13: Aktif | E13: LBK-013 | F13: SKG XI Lembak | G13: Flowline dari LBK-013 ke SKG XI Lembak | H13: GAS WELL | I13: SKG XI Lembak-GAS WELL | J13: 3200 | K13: 07-Jan-2009 | L13: 2009 | M13: 2009 | N13: 1 | P13: 32 | Q13: P1 | R13: 45730 | S13: Menyesuaikan panjang act | V13: PEP-PBM-PL-RLA-1801H | W13: PEP-PBM-PL-RE-1801H | AB13: 0 | AC13: 0 | AD13: 3130 | AE13: GOOD
A14: 9 | B14: Prabumulih | C14: Cluster Flowline Gas SKG XI Lembak | D14: Aktif | E14: LBK-014 | F14: SKG XI Lembak | G14: Flowline dari LBK-014 ke SKG XI Lembak | H14: GAS WELL | I14: SKG XI Lembak-GAS WELL | J14: 2010 | K14: 31-Jul-2009 | L14: 2009 | M14: 2009 | P14: 20.1 | Q14: P1 | R14: 45731 | S14: Menyesuaikan panjang act | V14: PEP-PBM-PL-RLA-1801I | W14: PEP-PBM-PL-RE-1801I | AB14: 0 | AC14: 0 | AD14: 0
A15: 10 | B15: Prabumulih | C15: Flowline Gas BRG-039 ke SP Beringin A | D15: Aktif | E15: BRG-039 | F15: SP Beringin A | G15: Flowline dari BRG-039 ke SP Beringin A | H15: GAS WELL | I15: SP Beringin A-GAS WELL | J15: 1342 | K15: 03-Nov-2022 | L15: 2022 | M15: 2022 | P15: 13.42 | Q15: P1 | R15: 45724 | S15: Menyesuaikan panjang act | V15: PEP-PBM-PL-RLA-1301 | W15: PEP-PBM-PL-RE-1301 | AB15: 0 | AC15: 0 | AD15: 0
A16: 11 | B16: Prabumulih | C16: Cluster Flowline Gas SPG Kuang | D16: Aktif | E16: KAG-004 | F16: SPG Kuang | G16: Flowline dari KAG-004 ke SPG Kuang | H16: GAS WELL | I16: SPG Kuang-GAS WELL | J16: 3820 | K16: 06-May-1968 | L16: 2005 | M16: 1968 | P16: 38.2 | Q16: P1 | R16: 45899 | V16: PEP-PBM-PL-RLA-1901A | W16: PEP-PBM-PL-RE-1901A | AB16: 0 | AC16: 0 | AD16: 0
A17: 12 | B17: Prabumulih | C17: Cluster Flowline Gas SPG Kuang | D17: Aktif | E17: KAG-026 | F17: SPG Kuang | G17: Flowline dari KAG-026 ke SPG Kuang | H17: GAS WELL | I17: SPG Kuang-GAS WELL | J17: 1600 | K17: 16-Jun-2016 | L17: 2016 | M17: 2016 | P17: 16 | Q17: P1 | R17: 45899 | V17: PEP-PBM-PL-RLA-1901B | W17: PEP-PBM-PL-RE-1901B | AB17: 0 | AC17: 0 | AD17: 0
A18: 13 | B18: Prabumulih | C18: Cluster Flowline Gas SPG Kuang | D18: Aktif | E18: KAG-027 | F18: SPG Kuang | G18: Flowline dari KAG-027 ke SPG Kuang | H18: GAS WELL | I18: SPG Kuang-GAS WELL | J18: 1600 | K18: 10-Aug-2016 | L18: 2016 | M18: 2016 | P18: 16 | Q18: P1 | R18: 45899 | V18: PEP-PBM-PL-RLA-1901C | W18: PEP-PBM-PL-RE-1901C | AB18: 0 | AC18: 0 | AD18: 0
A19: 14 | B19: Prabumulih | C19: Cluster Flowline Gas SPG Kuang | D19: Aktif | E19: KAG-028 | F19: SPG Kuang | G19: Flowline dari KAG-028 ke SPG Kuang | H19: GAS WELL | I19: SPG Kuang-GAS WELL | J19: 1600 | K19: 20-Nov-2016 | L19: 2016 | M19: 2016 | P19: 16 | Q19: P1 | R19: 45899 | V19: PEP-PBM-PL-RLA-1901D | W19: PEP-PBM-PL-RE-1901D | AB19: 0 | AC19: 0 | AD19: 0
A20: 15 | B20: Prabumulih | C20: Cluster Flowline Gas SPG Kuang | D20: Aktif | E20: SPR-001 | F20: SPG Kuang | G20: Flowline dari SPR-001 ke SPG Kuang | H20: GAS WELL | I20: SPG Kuang-GAS WELL | J20: 1600 | K20: 31-Dec-2010 | L20: 2010 | M20: 2010 | P20: 16 | Q20: P1 | R20: 45899 | V20: PEP-PBM-PL-RLA-1901E | W20: PEP-PBM-PL-RE-1901E | AB20: 0 | AC20: 0 | AD20: 0
A21: 16 | B21: Prabumulih | C21: Cluster Flowline Gas SPG Kuang | D21: Aktif | E21: KAG-008 | F21: SPG Kuang | G21: Flowline dari KAG-008 ke SPG Kuang | H21: GAS WELL | I21: SPG Kuang-GAS WELL | J21: 1600 | K21: 20-Jul-1969 | L21: 2005 | M21: 1969 | P21: 16 | Q21: P1 | R21: 45899 | V21: PEP-PBM-PL-RLA-1901F | W21: PEP-PBM-PL-RE-1901F | AB21: 0 | AC21: 0 | AD21: 0
A22: 17 | B22: Prabumulih | C22: Cluster Flowline Gas SPG Kuang | D22: Aktif | E22: KAG-014 | F22: SPG Kuang | G22: Flowline dari KAG-014 ke SPG Kuang | H22: GAS WELL | I22: SPG Kuang-GAS WELL | J22: 1600 | K22: 13-Feb-1974 | L22: 2005 | M22: 1974 | P22: 16 | Q22: P1 | R22: 45899 | V22: PEP-PBM-PL-RLA-1901G | W22: PEP-PBM-PL-RE-1901G | AB22: 0 | AC22: 0 | AD22: 0
A23: 18 | B23: Prabumulih | C23: Cluster Flowline Gas SP 1 Pagardewa | D23: Aktif | E23: PDS-001ST | F23: SP 1 Pagardewa | G23: Flowline dari PDS-001ST ke SP 1 Pagardewa | H23: GAS WELL | I23: SP 1 Pagardewa-GAS WELL | J23: 3891 | K23: 04-Nov-2010 | L23: 2010 | M23: 2010 | P23: 38.91 | Q23: P2 | R23: 45765 | S23: Menyesuaikan panjang act | V23: PEP-PBM-PL-RLA-1701A | W23: PEP-PBM-PL-RE-1701A | AB23: 0 | AC23: 0 | AD23: 0
A24: 19 | B24: Prabumulih | C24: Cluster Flowline Gas SP 1 Pagardewa | D24: Aktif | E24: PDW-007 | F24: SP 1 Pagardewa | G24: Flowline dari PDW-007 ke SP 1 Pagardewa | H24: GAS WELL | I24: SP 1 Pagardewa-GAS WELL | J24: 3088 | K24: 31-Dec-2014 | L24: 2014 | M24: 2014 | N24: 2 | P24: 30.88 | Q24: P2 | R24: 45762 | S24: Menyesuaikan panjang act | V24: PEP-PBM-PL-RLA-1701B | W24: PEP-PBM-PL-RE-1701B | AB24: 0 | AC24: 0 | AD24: 2080 | AE24: GOOD
A25: 20 | B25: Prabumulih | C25: Cluster Flowline Minyak SKG XI Lembak | D25: Aktif | E25: LBK-015 | F25: SKG XI Lembak | G25: Flowline dari LBK-015 ke SKG XI Lembak | H25: OIL WELL | I25: SKG XI Lembak-OIL WELL | J25: 505 | K25: 23-Jun-2020 | L25: 2020 | M25: 2020 | P25: 5.05 | Q25: P1 | R25: 45795 | S25: Menyesuaikan panjang act | V25: PEP-PBM-PL-RLA-401A | W25: PEP-PBM-PL-RE-401A | AB25: 0 | AC25: 0 | AD25: 0
A26: 21 | B26: Prabumulih | C26: Cluster Flowline Minyak SKG XI Lembak | D26: Aktif | E26: LBK-019 | F26: SKG XI Lembak | G26: Flowline dari LBK-019 ke SKG XI Lembak | H26: OIL WELL | I26: SKG XI Lembak-OIL WELL | J26: 1716 | K26: 28-Nov-2022 | L26: 2022 | M26: 2022 | N26: 14 | P26: 17.16 | Q26: P1 | R26: 45734 | S26: Menyesuaikan panjang act | V26: PEP-PBM-PL-RLA-401B | W26: PEP-PBM-PL-RE-401B | AB26: 40 | AC26: 0 | AD26: 2660 | AE26: BAD
A27: 22 | B27: Prabumulih | C27: Cluster Flowline Minyak SP 1 Gunung Kemala | D27: Aktif | E27: GNK-006 | F27: SP 1 Gunung Kemala | G27: Flowline dari GNK-006 ke SP 1 Gunung Kemala | H27: OIL WELL | I27: SP 1 Gunung Kemala-OIL WELL | J27: 1336 | K27: 09-Aug-1949 | L27: 2005 | M27: 1949 | N27: 1 | P27: 13.36 | Q27: P1 | R27: 45735 | S27: Menyesuaikan panjang act | V27: PEP-PBM-PL-RLA-501A | W27: PEP-PBM-PL-RE-501A | AB27: 30 | AC27: 0 | AD27: 1530 | AE27: BAD
A28: 23 | B28: Prabumulih | C28: Cluster Flowline Minyak SP 1 Gunung Kemala | D28: Aktif | E28: GNK-078 | F28: SP 1 Gunung Kemala | G28: Flowline dari GNK-078 ke SP 1 Gunung Kemala | H28: OIL WELL | I28: SP 1 Gunung Kemala-OIL WELL | J28: 1726 | K28: 17-Jun-1998 | L28: 2005 | M28: 1998 | N28: 1 | P28: 17.26 | Q28: P1 | R28: 45736 | S28: Menyesuaikan panjang act | V28: PEP-PBM-PL-RLA-501B | W28: PEP-PBM-PL-RE-501B | AB28: 0 | AC28: 0 | AD28: 0
A29: 24 | B29: Prabumulih | C29: Cluster Flowline Minyak SP 1 Gunung Kemala | D29: Aktif | E29: GNK-086 | F29: SP 1 Gunung Kemala | G29: Flowline dari GNK-086 ke SP 1 Gunung Kemala | H29: OIL WELL | I29: SP 1 Gunung Kemala-OIL WELL | J29: 1591 | K29: 19-Nov-2005 | L29: 2005 | M29: 2005 | P29: 15.91 | Q29: P1 | R29: 45736 | S29: Menyesuaikan panjang act | V29: PEP-PBM-PL-RLA-501C | W29: PEP-PBM-PL-RE-501C | AB29: 10 | AC29: 0 | AD29: 5680 | AE29: BAD
A30: 25 | B30: Prabumulih | C30: Cluster Flowline Minyak SP 2 Gunung Kemala | D30: Aktif | E30: GNK-088 | F30: SP 2 Gunung Kemala | G30: Flowline dari GNK-088 ke SP 2 Gunung Kemala | H30: OIL WELL | I30: SP 2 Gunung Kemala-OIL WELL | J30: 1071 | K30: 07-Sep-2007 | L30: 2007 | M30: 2007 | N30: 1 | P30: 10.71 | Q30: P1 | R30: 45728 | S30: Menyesuaikan panjang act | V30: PEP-PBM-PL-RLA-1101A | W30: PEP-PBM-PL-RE-1101A | AB30: 0 | AC30: 0 | AD30: 0
A31: 26 | B31: Prabumulih | C31: Cluster Flowline Minyak SP 2 Gunung Kemala | D31: Aktif | E31: GNK-089ST | F31: SP 2 Gunung Kemala | G31: Flowline dari GNK-089ST ke SP 2 Gunung Kemala | H31: OIL WELL | I31: SP 2 Gunung Kemala-OIL WELL | J31: 1576 | K31: 17-Mar-2008 | L31: 2008 | M31: 2008 | P31: 15.76 | Q31: P1 | R31: 45728 | S31: Menyesuaikan panjang act | V31: PEP-PBM-PL-RLA-1101B | W31: PEP-PBM-PL-RE-1101B | AB31: 0 | AC31: 0 | AD31: 0
A32: 27 | B32: Prabumulih | C32: Cluster Flowline Minyak SP 2 Gunung Kemala | D32: Aktif | E32: GNK-092 | F32: SP 2 Gunung Kemala | G32: Flowline dari GNK-092 ke SP 2 Gunung Kemala | H32: OIL WELL | I32: SP 2 Gunung Kemala-OIL WELL | J32: 1927 | K32: 24-Jun-2012 | L32: 2012 | M32: 2012 | N32: 10 | P32: 19.27 | Q32: P1 | R32: 45728 | S32: Menyesuaikan panjang act | V32: PEP-PBM-PL-RLA-1101C | W32: PEP-PBM-PL-RE-1101C | AB32: 0 | AC32: 0 | AD32: 0
A33: 28 | B33: Prabumulih | C33: Cluster Flowline Minyak SP 2 Gunung Kemala | D33: Aktif | E33: GNK-094 | F33: SP 2 Gunung Kemala | G33: Flowline dari GNK-094 ke SP 2 Gunung Kemala | H33: OIL WELL | I33: SP 2 Gunung Kemala-OIL WELL | J33: 1377 | K33: 24-Aug-2012 | L33: 2012 | M33: 2012 | N33: 2 | O33: RK ABI Field | P33: 13.77 | Q33: P1 | R33: 45762 | S33: Menyesuaikan panjang act | V33: PEP-PBM-PL-RLA-1101D | W33: PEP-PBM-PL-RE-1101D | AB33: 0 | AC33: 0 | AD33: 0
A34: 29 | B34: Prabumulih | C34: Cluster Flowline Minyak SP 2 Gunung Kemala | D34: Aktif | E34: GNK-069 | F34: SP 2 Gunung Kemala | G34: Flowline dari GNK-069 ke SP 2 Gunung Kemala | H34: OIL WELL | I34: SP 2 Gunung Kemala-OIL WELL | J34: 1088 | P34: 10.88 | R34: 45732 | S34: Menyesuaikan panjang act | V34: PEP-PBM-PL-RLA-1101E | W34: PEP-PBM-PL-RE-1101E | AB34: 0 | AC34: 0 | AD34: 0
A35: 30 | B35: Prabumulih | C35: Flowline Minyak TLJ-109 ke SP 2 Talang Jimar | D35: Aktif | E35: TLJ-109 | F35: SP 2 Talang Jimar | G35: Flowline dari TLJ-109 ke SP 2 Talang Jimar | H35: OIL WELL | I35: SP 2 Talang Jimar-OIL WELL | J35: 1238 | K35: 12-Aug-1943 | L35: 2005 | M35: 1943 | N35: 8 | O35: RK ABI Field | P35: 12.38 | Q35: P2 | R35: 45735 | S35: Menyesuaikan panjang act | V35: PEP-PBM-PL-RLA-701 | W35: PEP-PBM-PL-DBS-701 | AB35: 0 | AC35: 0 | AD35: 0
A36: 31 | B36: Prabumulih | C36: Flowline Minyak GNK-082 ke SP 3 Gunung Kemala | D36: Aktif | E36: GNK-082 | F36: SP 3 Gunung Kemala | G36: Flowline dari GNK-082 ke SP 3 Gunung Kemala | H36: OIL WELL | I36: SP 3 Gunung Kemala-OIL WELL | J36: 2725 | K36: 09-Oct-2003 | L36: 2005 | M36: 2003 | P36: 27.25 | Q36: P1 | R36: 45737 | S36: Menyesuaikan panjang act | V36: PEP-PBM-PL-RLA-601 | W36: PEP-PBM-PL-DBS-601 | AB36: 0 | AC36: 0 | AD36: 0
A37: 32 | B37: Prabumulih | C37: Flowline Minyak TLJ-156 ke SP 5 Talang Jimar | D37: Suspend | E37: TLJ-156 | F37: SP 5 Talang Jimar | G37: Flowline dari TLJ-156 ke SP 5 Talang Jimar | H37: OIL WELL | I37: SP 5 Talang Jimar-OIL WELL | J37: 756 | K37: #N/A | O37: Add RK ABI Field | P37: 7.56 | Q37: P2 | R37: 45735 | V37: PEP-PBM-PL-RLA-801 | W37: PEP-PBM-PL-DBS-801 | AB37: 0 | AC37: 0 | AD37: 0
A38: 33 | B38: Prabumulih | C38: Flowline TLJ-221 ke Minyak SP 6 Talang Jimar | D38: Aktif | E38: TLJ-211 | F38: SP 6 Talang Jimar | G38: Flowline dari TLJ-211 ke SP 6 Talang Jimar | H38: OIL WELL | I38: SP 6 Talang Jimar-OIL WELL | J38: 1177 | K38: 18-May-2004 | L38: 2005 | M38: 2004 | O38: RK ABI Field | P38: 11.77 | Q38: P2 | R38: 45740 | S38: Menyesuaikan panjang act | V38: PEP-PBM-PL-RLA-901 | W38: PEP-PBM-PL-DBS-901 | AB38: 0 | AC38: 0 | AD38: 0
A39: 34 | B39: Prabumulih | C39: Cluster Flowline Minyak SP 9 Talang Jimar | D39: Aktif | E39: TLJ-071 | F39: SP 9 Talang Jimar | G39: Flowline dari TLJ-071 ke SP 9 Talang Jimar | H39: OIL WELL | I39: SP 9 Talang Jimar-OIL WELL | J39: 2150 | K39: 04-Dec-1940 | L39: 2005 | M39: 1940 | N39: 1 | P39: 21.5 | Q39: P1 | R39: 45703 | V39: PEP-PBM-PL-RLA-101A | W39: PEP-PBM-PL-RE-101A | AB39: 0 | AC39: 0 | AD39: 1460 | AE39: GOOD
A40: 35 | B40: Prabumulih | C40: Cluster Flowline Minyak SP 9 Talang Jimar | D40: Aktif | E40: TLJ-003 | F40: SP 9 Talang Jimar | G40: Flowline dari TLJ-003 ke SP 9 Talang Jimar | H40: OIL WELL | I40: SP 9 Talang Jimar-OIL WELL | J40: 1800 | K40: 07-Feb-1938 | L40: 2005 | M40: 1938 | N40: 6 | P40: 18 | Q40: P1 | R40: 45703 | V40: PEP-PBM-PL-RLA-101B | W40: PEP-PBM-PL-RE-101B | AB40: 0 | AC40: 0 | AD40: 0
A41: 36 | B41: Prabumulih | C41: Cluster Flowline Minyak SP 9 Talang Jimar | D41: Aktif | E41: TLJ-012 | F41: SP 9 Talang Jimar | G41: Flowline dari TLJ-012 ke SP 9 Talang Jimar | H41: OIL WELL | I41: SP 9 Talang Jimar-OIL WELL | J41: 1250 | K41: 19-Jul-1938 | L41: 2005 | M41: 1938 | P41: 12.5 | Q41: P1 | R41: 45702 | V41: PEP-PBM-PL-RLA-101C | W41: PEP-PBM-PL-RE-101C | AB41: 0 | AC41: 0 | AD41: 1470 | AE41: GOOD
A42: 37 | B42: Prabumulih | C42: Cluster Flowline Minyak SP 9 Talang Jimar | D42: Aktif | E42: TLJ-208 | F42: SP 9 Talang Jimar | G42: Flowline dari TLJ-208 ke SP 9 Talang Jimar | H42: OIL WELL | I42: SP 9 Talang Jimar-OIL WELL | J42: 1236 | K42: 16-Feb-2003 | L42: 2005 | M42: 2003 | O42: RK ABI Field | P42: 12.36 | Q42: P1 | R42: 45699 | V42: PEP-PBM-PL-RLA-101D | W42: PEP-PBM-PL-RE-101D | AB42: 0 | AC42: 0 | AD42: 0
A43: 38 | B43: Prabumulih | C43: Cluster Flowline Minyak SP 9 Talang Jimar | D43: Aktif | E43: TLJ-213 | F43: SP 9 Talang Jimar | G43: Flowline dari TLJ-213 ke SP 9 Talang Jimar | H43: OIL WELL | I43: SP 9 Talang Jimar-OIL WELL | J43: 1308 | K43: 21-Jun-2004 | L43: 2005 | M43: 2004 | N43: 1 | O43: RK ABI Field | P43: 13.08 | Q43: P1 | R43: 45708 | V43: PEP-PBM-PL-RLA-101E | W43: PEP-PBM-PL-RE-101E | AB43: 40 | AC43: 0 | AD43: 2000 | AE43: BAD
A44: 39 | B44: Prabumulih | C44: Cluster Flowline Minyak SP 9 Talang Jimar | D44: Aktif | E44: TLJ-215 | F44: SP 9 Talang Jimar | G44: Flowline dari TLJ-215 ke SP 9 Talang Jimar | H44: OIL WELL | I44: SP 9 Talang Jimar-OIL WELL | J44: 1440 | K44: 26-Nov-2004 | L44: 2005 | M44: 2004 | O44: RK ABI Field | P44: 14.4 | Q44: P1 | R44: 45700 | V44: PEP-PBM-PL-RLA-101F | W44: PEP-PBM-PL-RE-101F | AB44: 0 | AC44: 0 | AD44: 0
...
